<?xml version="1.0" encoding="utf-8" ?>
<!-- This URDF was automatically created by SolidWorks to URDF Exporter! Originally created by Stephen Brawner (brawner@gmail.com) 
     Commit Version: 1.6.0-4-g7f85cfe  Build Version: 1.6.7995.38578
     For more information, please see http://wiki.ros.org/sw_urdf_exporter -->
<robot name="arm_assembly">
    <link name="base_link">
        
<inertial>
            <origin xyz="1.03582841131364E-18 0.015606490089144 1.93574980271696E-18" rpy="0 0 0" />
            <mass value="0.93972387307473" />
            <inertia ixx="0.00251429022255044" ixy="8.65861551705636E-21" ixz="-7.37485241366082E-20" iyy="0.0044229329573873" iyz="2.27711298016934E-20" izz="0.0021336882069818" />
        </inertial>

        <visual>
            <origin xyz="0 0 0" rpy="0 0 0" />
            <geometry>
                <mesh filename="package://arm_assembly/meshes/base_link.STL" />
            </geometry>
            <material name="">
                <color rgba="0.792156862745098 0.819607843137255 0.933333333333333 1" />
            </material>
        </visual>
        <collision>
            <origin xyz="0 0 0" rpy="0 0 0" />
            <geometry>
                <mesh filename="package://arm_assembly/meshes/base_link.STL" />
            </geometry>
        </collision>
    </link>
    <link name="shoulderBase_link">
        
<inertial>
            <origin xyz="-0.0122586821821901 0.128577249577976 -0.00370544350042927" rpy="0 0 0" />
            <mass value="0.996366805002727" />
            <inertia ixx="0.00652370094208947" ixy="0.0010646616036529" ixz="0.000283127005277364" iyy="0.0050231810993567" iyz="6.82113719161566E-05" izz="0.0086334538259584" />
        </inertial>

        <visual>
            <origin xyz="0 0 0" rpy="0 0 0" />
            <geometry>
                <mesh filename="package://arm_assembly/meshes/shoulderBase_link.STL" />
            </geometry>
            <material name="">
                <color rgba="0.792156862745098 0.819607843137255 0.933333333333333 1" />
            </material>
        </visual>
        <collision>
            <origin xyz="0 0 0" rpy="0 0 0" />
            <geometry>
                <mesh filename="package://arm_assembly/meshes/shoulderBase_link.STL" />
            </geometry>
        </collision>
    </link>
    <joint name="turntable" type="continuous">
        <origin xyz="0 0 0.035865" rpy="1.5708 0 -0.25129" />
        <parent link="base_link" />
        <child link="shoulderBase_link" />
        <axis xyz="0 1 0" />
        <limit effort="50" velocity="1.5" lower="-3.1" upper="3.1" />
    </joint>
    <link name="upperArm_link">
        
<inertial>
            <origin xyz="0.0143973999054565 -3.20061625687929E-05 0.279348384794928" rpy="0 0 0" />
            <mass value="0.985210343915811" />
            <inertia ixx="0.0237982224738339" ixy="-8.87977733299251E-07" ixz="-0.00388532856230119" iyy="0.0293594722597602" iyz="-7.12944369971275E-06" izz="0.00625034839320104" />
        </inertial>

        <visual>
            <origin xyz="0 0 0" rpy="0 0 0" />
            <geometry>
                <mesh filename="package://arm_assembly/meshes/upperArm_link.STL" />
            </geometry>
            <material name="">
                <color rgba="0.792156862745098 0.819607843137255 0.933333333333333 1" />
            </material>
        </visual>
        <collision>
            <origin xyz="0 0 0" rpy="0 0 0" />
            <geometry>
                <mesh filename="package://arm_assembly/meshes/upperArm_link.STL" />
            </geometry>
        </collision>
    </link>
    <joint name="shoulder" type="continuous">
        <origin xyz="0 0.18098 0.043071" rpy="-1.1021 0 0" />
        <parent link="shoulderBase_link" />
        <child link="upperArm_link" />
        <axis xyz="1 0 0" />
        <limit effort="50" velocity="1.5" lower="-0.349" upper="0.78539" />
    </joint>
    <link name="forarm_link">
        
<inertial>
            <origin xyz="1.84574577843932E-15 0.0550154986611603 0.120152803034247" rpy="0 0 0" />
            <mass value="0.517796101730459" />
            <inertia ixx="0.00404850874710771" ixy="2.11419423634673E-18" ixz="-1.54871504075976E-17" iyy="0.00375548329392274" iyz="-0.000377385363706529" izz="0.000788327838226562" />
        </inertial>

        <visual>
            <origin xyz="0 0 0" rpy="0 0 0" />
            <geometry>
                <mesh filename="package://arm_assembly/meshes/forarm_link.STL" />
            </geometry>
            <material name="">
                <color rgba="0.792156862745098 0.819607843137255 0.933333333333333 1" />
            </material>
        </visual>
        <collision>
            <origin xyz="0 0 0" rpy="0 0 0" />
            <geometry>
                <mesh filename="package://arm_assembly/meshes/forarm_link.STL" />
            </geometry>
        </collision>
    </link>
    <joint name="elbow" type="continuous">
        <origin xyz="0 0 0.46634" rpy="2.4936 0 0" />
        <parent link="upperArm_link" />
        <child link="forarm_link" />
        <axis xyz="1 0 0" />
        <limit effort="50" velocity="1.5" lower="0" upper="3.1" />
    </joint>
    <link name="wirstBase_link">
        
<inertial>
            <origin xyz="-1.94289029309402E-16 -1.66533453693773E-15 0.0987034845564234" rpy="0 0 0" />
            <mass value="0.301763082175337" />
            <inertia ixx="0.00210344289702837" ixy="-2.71050543121376E-19" ixz="-2.24971950790742E-18" iyy="0.00305016250706558" iyz="1.85669622038143E-18" izz="0.00107609106501786" />
        </inertial>

        <visual>
            <origin xyz="0 0 0" rpy="0 0 0" />
            <geometry>
                <mesh filename="package://arm_assembly/meshes/wirstBase_link.STL" />
            </geometry>
            <material name="">
                <color rgba="0.792156862745098 0.819607843137255 0.933333333333333 1" />
            </material>
        </visual>
        <collision>
            <origin xyz="0 0 0" rpy="0 0 0" />
            <geometry>
                <mesh filename="package://arm_assembly/meshes/wirstBase_link.STL" />
            </geometry>
        </collision>
    </link>
    <joint name="forearm_roll" type="continuous">
        <origin xyz="0 0.04445 0.2285" rpy="0 0 0" />
        <parent link="forarm_link" />
        <child link="wirstBase_link" />
        <axis xyz="0 0 1" />
        <limit effort="50" velocity="1.5" lower="-3.1" upper="3.1" />
    </joint>
    <link name="wrist_link">
        
<inertial>
            <origin xyz="4.30211422042248E-16 -2.77555756156289E-17 0" rpy="0 0 0" />
            <mass value="0.447707117943176" />
            <inertia ixx="0.000367702266904795" ixy="1.79994501291539E-19" ixz="-7.45388993583784E-19" iyy="0.000843427086265753" iyz="-1.35525271560688E-20" izz="0.00084474612356066" />
        </inertial>

        <visual>
            <origin xyz="0 0 0" rpy="0 0 0" />
            <geometry>
                <mesh filename="package://arm_assembly/meshes/wrist_link.STL" />
            </geometry>
            <material name="">
                <color rgba="0.792156862745098 0.819607843137255 0.933333333333333 1" />
            </material>
        </visual>
        <collision>
            <origin xyz="0 0 0" rpy="0 0 0" />
            <geometry>
                <mesh filename="package://arm_assembly/meshes/wrist_link.STL" />
            </geometry>
        </collision>
    </link>
    <joint name="wrist_pitch" type="continuous">
        <origin xyz="0 0 0.23716" rpy="-1.333 0 0" />
        <parent link="wirstBase_link" />
        <child link="wrist_link" />
        <axis xyz="1 0 0" />
        <limit effort="50" velocity="1.5" lower="-1.5707963267948966" upper="1.5707963267948966" />
    </joint>
    <link name="manipulator_link">
        
<inertial>
            <origin xyz="-0.000730323740460503 -0.000899365669252 0.0490560099953423" rpy="0 0 0" />
            <mass value="0.397420225554811" />
            <inertia ixx="0.00159684305263878" ixy="-3.07243227891656E-06" ixz="2.53235579936151E-05" iyy="0.0016343224414688" iyz="5.00292290874635E-05" izz="0.000256322563994287" />
        </inertial>

        <visual>
            <origin xyz="0 0 0" rpy="0 0 0" />
            <geometry>
                <mesh filename="package://arm_assembly/meshes/manipulator_link.STL" />
            </geometry>
            <material name="">
                <color rgba="0.792156862745098 0.819607843137255 0.933333333333333 1" />
            </material>
        </visual>
        <collision>
            <origin xyz="0 0 0" rpy="0 0 0" />
            <geometry>
                <mesh filename="package://arm_assembly/meshes/manipulator_link.STL" />
            </geometry>
        </collision>
    </link>
    <joint name="wrist_roll" type="continuous">
        <origin xyz="0 0 0" rpy="0 0 0.096862" />
        <parent link="wrist_link" />
        <child link="manipulator_link" />
        <axis xyz="0 0 1" />
        <limit effort="50" velocity="1.5" lower="-3.15" upper="3.15" />
    </joint>
    
<transmission name="trans_turntable">
        <type>transmission_interface/SimpleTransmission</type>
        <joint name="turntable">
            <hardwareInterface>hardware_interface/EffortJointInterface</hardwareInterface>
        </joint>
        <actuator name="turntable_motor">
            <hardwareInterface>hardware_interface/EffortJointInterface</hardwareInterface>
            <mechanicalReduction>1</mechanicalReduction>
        </actuator>
    </transmission>
    <transmission name="trans_shoulder">
        <type>transmission_interface/SimpleTransmission</type>
        <joint name="shoulder">
            <hardwareInterface>hardware_interface/EffortJointInterface</hardwareInterface>
        </joint>
        <actuator name="shoulder_motor">
            <hardwareInterface>hardware_interface/EffortJointInterface</hardwareInterface>
            <mechanicalReduction>1</mechanicalReduction>
        </actuator>
    </transmission>
    <transmission name="trans_elbow">
        <type>transmission_interface/SimpleTransmission</type>
        <joint name="elbow">
            <hardwareInterface>hardware_interface/EffortJointInterface</hardwareInterface>
        </joint>
        <actuator name="elbow_motor">
            <hardwareInterface>hardware_interface/EffortJointInterface</hardwareInterface>
            <mechanicalReduction>1</mechanicalReduction>
        </actuator>
    </transmission>
    <transmission name="trans_forearm_roll">
        <type>transmission_interface/SimpleTransmission</type>
        <joint name="forearm_roll">
            <hardwareInterface>hardware_interface/EffortJointInterface</hardwareInterface>
        </joint>
        <actuator name="forearm_roll_motor">
            <hardwareInterface>hardware_interface/EffortJointInterface</hardwareInterface>
            <mechanicalReduction>1</mechanicalReduction>
        </actuator>
    </transmission>
    <transmission name="trans_wrist_pitch">
        <type>transmission_interface/SimpleTransmission</type>
        <joint name="wrist_pitch">
            <hardwareInterface>hardware_interface/EffortJointInterface</hardwareInterface>
        </joint>
        <actuator name="wrist_pitch_motor">
            <hardwareInterface>hardware_interface/EffortJointInterface</hardwareInterface>
            <mechanicalReduction>1</mechanicalReduction>
        </actuator>
    </transmission>
    <transmission name="trans_wrist_roll">
        <type>transmission_interface/SimpleTransmission</type>
        <joint name="wrist_roll">
            <hardwareInterface>hardware_interface/EffortJointInterface</hardwareInterface>
        </joint>
        <actuator name="wrist_roll_motor">
            <hardwareInterface>hardware_interface/EffortJointInterface</hardwareInterface>
            <mechanicalReduction>1</mechanicalReduction>
        </actuator>
    </transmission>
    <gazebo>
        <plugin name="gazebo_ros_control" filename="libgazebo_ros_control.so">
            <robotNamespace>/</robotNamespace>
        </plugin>
    </gazebo>
</robot>