<?xml version="1.0" encoding="utf-8"?>
<!-- This URDF was automatically created by SolidWorks to URDF Exporter! Originally created by Stephen Brawner (brawner@gmail.com) 
     Commit Version: 1.6.0-4-g7f85cfe  Build Version: 1.6.7995.38578
     For more information, please see http://wiki.ros.org/sw_urdf_exporter -->
<robot
  name="wroboarm_23">
  <link
    name="base_link">
    <inertial>
      <origin
        xyz="9.1830074983592E-19 -9.80159456515381E-19 0.015606490089144"
        rpy="0 0 0" />
      <mass
        value="0.93972387307473" />
      <inertia
        ixx="0.00251429022255044"
        ixy="7.37485241366082E-20"
        ixz="8.66637218064247E-21"
        iyy="0.0021336882069818"
        iyz="1.14091331088149E-19"
        izz="0.0044229329573873" />
    </inertial>
    <visual>
      <origin
        xyz="0 0 0"
        rpy="0 0 0" />
      <geometry>
        <mesh
          filename="package://wroboarm_23/meshes/base_link.STL" />
      </geometry>
      <material
        name="">
        <color
          rgba="0.792156862745098 0.819607843137255 0.933333333333333 1" />
      </material>
    </visual>
    <collision>
      <origin
        xyz="0 0 0"
        rpy="0 0 0" />
      <geometry>
        <mesh
          filename="package://wroboarm_23/meshes/base_link.STL" />
      </geometry>
    </collision>
  </link>
  <link
    name="turntable_link">
    <inertial>
      <origin
        xyz="-0.01225868218219 0.128577249577976 -0.00370544350042927"
        rpy="0 0 0" />
      <mass
        value="0.996366805002726" />
      <inertia
        ixx="0.00652370094208946"
        ixy="0.0010646616036529"
        ixz="0.000283127005277363"
        iyy="0.0050231810993567"
        iyz="6.82113719161566E-05"
        izz="0.00863345382595838" />
    </inertial>
    <visual>
      <origin
        xyz="0 0 0"
        rpy="0 0 0" />
      <geometry>
        <mesh
          filename="package://wroboarm_23/meshes/turntable_link.STL" />
      </geometry>
      <material
        name="">
        <color
          rgba="0.792156862745098 0.819607843137255 0.933333333333333 1" />
      </material>
    </visual>
    <collision>
      <origin
        xyz="0 0 0"
        rpy="0 0 0" />
      <geometry>
        <mesh
          filename="package://wroboarm_23/meshes/turntable_link.STL" />
      </geometry>
    </collision>
  </link>
  <joint
    name="turntable_joint"
    type="revolute">
    <origin
      xyz="0 0 0.035865"
      rpy="1.5708 0 -0.84509" />
    <parent
      link="base_link" />
    <child
      link="turntable_link" />
    <axis
      xyz="0 1 0" />
    <limit effort="50" velocity="1.5" lower="0" upper="1.57" />
  </joint>
  <link
    name="upperArm_link">
    <inertial>
      <origin
        xyz="0.0143973999054599 -3.20061625693202E-05 0.279348384794928"
        rpy="0 0 0" />
      <mass
        value="0.985210343915811" />
      <inertia
        ixx="0.0237982224738338"
        ixy="-8.8797773328906E-07"
        ixz="-0.00388532856230116"
        iyy="0.0293594722597601"
        iyz="-7.129443699684E-06"
        izz="0.00625034839320102" />
    </inertial>
    <visual>
      <origin
        xyz="0 0 0"
        rpy="0 0 0" />
      <geometry>
        <mesh
          filename="package://wroboarm_23/meshes/upperArm_link.STL" />
      </geometry>
      <material
        name="">
        <color
          rgba="0.792156862745098 0.819607843137255 0.933333333333333 1" />
      </material>
    </visual>
    <collision>
      <origin
        xyz="0 0 0"
        rpy="0 0 0" />
      <geometry>
        <mesh
          filename="package://wroboarm_23/meshes/upperArm_link.STL" />
      </geometry>
    </collision>
  </link>
  <joint
    name="shoulder_joint"
    type="revolute">
    <origin
      xyz="0 0.18098 0.043071"
      rpy="-1.5572 0 0" />
    <parent
      link="turntable_link" />
    <child
      link="upperArm_link" />
    <axis
      xyz="-1 0 0" />
    <limit effort="50" velocity="1.5" lower="0" upper="1.57" />
  </joint>
  <link
    name="forearm_link">
    <inertial>
      <origin
        xyz="-4.1286418728248E-16 0.0550154986611603 0.120152803034247"
        rpy="0 0 0" />
      <mass
        value="0.51779610173045" />
      <inertia
        ixx="0.00404850874710764"
        ixy="-4.33680868994202E-19"
        ixz="2.87313575708659E-18"
        iyy="0.00375548329392275"
        iyz="-0.000377385363706531"
        izz="0.000788327838226511" />
    </inertial>
    <visual>
      <origin
        xyz="0 0 0"
        rpy="0 0 0" />
      <geometry>
        <mesh
          filename="package://wroboarm_23/meshes/forearm_link.STL" />
      </geometry>
      <material
        name="">
        <color
          rgba="0.792156862745098 0.819607843137255 0.933333333333333 1" />
      </material>
    </visual>
    <collision>
      <origin
        xyz="0 0 0"
        rpy="0 0 0" />
      <geometry>
        <mesh
          filename="package://wroboarm_23/meshes/forearm_link.STL" />
      </geometry>
    </collision>
  </link>
  <joint
    name="elbowPitch_joint"
    type="revolute">
    <origin
      xyz="0 0 0.46634"
      rpy="2.7009 0 0" />
    <parent
      link="upperArm_link" />
    <child
      link="forearm_link" />
    <axis
      xyz="-1 0 0" />
    <limit effort="50" velocity="1.5" lower="0" upper="1.57" />
  </joint>
  <link
    name="wrist_link">
    <inertial>
      <origin
        xyz="-2.77555756156289E-17 5.55111512312578E-17 0.096820252622317"
        rpy="0 0 0" />
      <mass
        value="0.301763082175336" />
      <inertia
        ixx="0.00210344289702837"
        ixy="1.30104260698261E-18"
        ixz="5.14996031930615E-19"
        iyy="0.00305016250706558"
        iyz="-1.15196480826585E-18"
        izz="0.00107609106501786" />
    </inertial>
    <visual>
      <origin
        xyz="0 0 0"
        rpy="0 0 0" />
      <geometry>
        <mesh
          filename="package://wroboarm_23/meshes/wrist_link.STL" />
      </geometry>
      <material
        name="">
        <color
          rgba="0.792156862745098 0.819607843137255 0.933333333333333 1" />
      </material>
    </visual>
    <collision>
      <origin
        xyz="0 0 0"
        rpy="0 0 0" />
      <geometry>
        <mesh
          filename="package://wroboarm_23/meshes/wrist_link.STL" />
      </geometry>
    </collision>
  </link>
  <joint
    name="elbowRoll_joint"
    type="revolute">
    <origin
      xyz="0 0.04445 0.23038"
      rpy="0 0 0" />
    <parent
      link="forearm_link" />
    <child
      link="wrist_link" />
    <axis
      xyz="0 0 1" />
    <limit effort="50" velocity="1.5" lower="0" upper="1.57" />
  </joint>
  <link
    name="carpus_link">
    <inertial>
      <origin
        xyz="5.55111512312578E-17 5.55111512312578E-17 0"
        rpy="0 0 0" />
      <mass
        value="0.447707117943177" />
      <inertia
        ixx="0.000367702266904795"
        ixy="7.04731412115578E-19"
        ixz="1.62630325872826E-19"
        iyy="0.000843427086265753"
        iyz="0"
        izz="0.000844746123560661" />
    </inertial>
    <visual>
      <origin
        xyz="0 0 0"
        rpy="0 0 0" />
      <geometry>
        <mesh
          filename="package://wroboarm_23/meshes/carpus_link.STL" />
      </geometry>
      <material
        name="">
        <color
          rgba="0.792156862745098 0.819607843137255 0.933333333333333 1" />
      </material>
    </visual>
    <collision>
      <origin
        xyz="0 0 0"
        rpy="0 0 0" />
      <geometry>
        <mesh
          filename="package://wroboarm_23/meshes/carpus_link.STL" />
      </geometry>
    </collision>
  </link>
  <joint
    name="wristPitch_joint"
    type="revolute">
    <origin
      xyz="0 0 0.23528"
      rpy="0 0 0" />
    <parent
      link="wrist_link" />
    <child
      link="carpus_link" />
    <axis
      xyz="-1 0 0" />
    <limit effort="50" velocity="1.5" lower="0" upper="1.57" />
  </joint>
  <link
    name="endEffector_link">
    <inertial>
      <origin
        xyz="-0.000725623905114631 -0.000893578002320872 0.0499824104113341"
        rpy="0 0 0" />
      <mass
        value="0.399994299548626" />
      <inertia
        ixx="0.00169604127916281"
        ixy="-3.07411212276679E-06"
        ixz="2.57918978917245E-05"
        iyy="0.00173351996343527"
        iyz="5.0605971705242E-05"
        izz="0.000256533582960489" />
    </inertial>
    <visual>
      <origin
        xyz="0 0 0"
        rpy="0 0 0" />
      <geometry>
        <mesh
          filename="package://wroboarm_23/meshes/endEffector_link.STL" />
      </geometry>
      <material
        name="">
        <color
          rgba="0.792156862745098 0.819607843137255 0.933333333333333 1" />
      </material>
    </visual>
    <collision>
      <origin
        xyz="0 0 0"
        rpy="0 0 0" />
      <geometry>
        <mesh
          filename="package://wroboarm_23/meshes/endEffector_link.STL" />
      </geometry>
    </collision>
  </link>
  <joint
    name="wristRoll_link"
    type="revolute">
    <origin
      xyz="0 0 0"
      rpy="0 0 0" />
    <parent
      link="carpus_link" />
    <child
      link="endEffector_link" />
    <axis
      xyz="0 0 1" />
    <limit effort="50" velocity="1.5" lower="0" upper="1.57" />
  </joint>
</robot>