<?xml version="1.0" ?>
<!-- =================================================================================== -->
<!-- |    This document was autogenerated by xacro from src/gazebot24/config/robot.urdf | -->
<!-- |    EDITING THIS FILE BY HAND IS NOT RECOMMENDED                                 | -->
<!-- =================================================================================== -->
<robot name="robot">
  <!-- To include it add the following line -->
  <!-- <xacro:include filename="example_gazebo.xacro" /> -->
  <!-- Gazebo is unable to use the same <material> tags that are already in the URDF (that RViz uses). -->
  <!-- Instead, we need to add gazebo tags for our links that refer to Gazebo materials -->
  <gazebo reference="base_link">
    <material>Gazebo/Green</material>
  </gazebo>
  <!-- Gazebo requires the use of plugins to interact with other systems such as ROS. -->
  <!-- This plugin will publish the joint_states for the selected joints 
            (which robot_state_publisher can then use to broadcast the approprate tf). 
            TODO: Add all the possible joints to this list-->
  <gazebo>
    <plugin filename="libgazebo_ros_joint_state_publisher.so" name="gazebo_ros_joint_state_publisher">
      <update_rate>20</update_rate>
      <joint_name>camera_vertical_link</joint_name>
      <joint_name>cam_horizontal_link</joint_name>
      <joint_name>lr_to_base_link</joint_name>
      <joint_name>lbb_to_lb</joint_name>
      <joint_name>rrb_to_base_link</joint_name>
      <joint_name>rbb_to_rb</joint_name>
    </plugin>
  </gazebo>
  <!-- This plugin will read a JointTrajectory message from the /set_joint_trajectory topic 
            and move the machine accordingly. It's a bit clunky but it works. -->
  <!-- You'll probably want to add damping to the joints to stop them it flopping around. 
            e.g. <dynamics damping="10.0" friction="10.0"/> -->
  <!-- Here's an example message to publish to test it:
            ros2 topic pub -1 /set_joint_trajectory trajectory_msgs/msg/JointTrajectory  '{header: {frame_id: world}, joint_names: [slider_joint, arm_joint], points: [  {positions: {0.8,0.6}} ]}' -->
  <gazebo>
    <plugin filename="libgazebo_ros_joint_pose_trajectory.so" name="gazebo_ros_joint_pose_trajectory">
      <update_rate>2</update_rate>
    </plugin>
  </gazebo>
  <!-- The next section shows an example of adding a sensor, in this case a depth camera. -->
  <!-- Due to a quirk of how cameras work, an extra joint/link is required to create an
            "optical frame" for the sensor. That isn't the focus for this tutorial, but you can
            look at https://www.ros.org/reps/rep-0103.html#suffix-frames for slightly more information. -->
  <!-- First, create the link and joint for the optical frame -->
  <joint name="camera_optical_joint" type="fixed">
    <origin rpy="-1.571 0 -1.571" xyz="0 0 0"/>
    <parent link="camera_link"/>
    <child link="camera_link_optical"/>
  </joint>
  <link name="camera_link_optical"/>
  <!-- Add a gazebo tag for the ORIGINAL camera_link (but in the plugin we reference the optical frame so that ROS can orient things correctly) -->
  <!-- Within the gazebo tag we have the sensor tag, and inside that there is (among other things) the camera tag with the camera parameters, 
            and the plugin tag with some extra parameters the plugin needs. -->
  <!-- Note that although visualise is set to true, it won't actually visualise the depth camera in gazebo. To see the preview, 
            try swapping "depth" to "camera"-->
  <!-- Camera Definition in Gazebo-->
  <gazebo reference="topCamera">
    <sensor name="camera_camera_sensor" type="camera">
      <update_rate>20.0</update_rate>
      <camera>
        <pose>0.035 0 0.078 0 -1.6 0</pose>
        <horizontal_fov> 1.5 </horizontal_fov>
        <image>
          <format>R8G8B8</format>
          <width>640</width>
          <height>480</height>
        </image>
        <clip>
          <near>0.01</near>
          <far>100</far>
        </clip>
      </camera>
      <plugin filename="libgazebo_ros_camera.so" name="camera_camera_controller">
        <frame_name>topCamera</frame_name>
        <min_depth>0.1</min_depth>
        <max_depth>500</max_depth>
      </plugin>
    </sensor>
  </gazebo>
  <gazebo reference="laser_frame">
    <material>Gazebo/Red</material>
    <sensor name="laser" type="ray">
      <pose> 0 0 0 0 0 0 </pose>
      <visualize>true</visualize>
      <update_rate>10</update_rate>
      <ray>
        <scan>
          <horizontal>
            <samples>360</samples>
            <min_angle>-3.14</min_angle>
            <max_angle>3.14</max_angle>
          </horizontal>
        </scan>
        <range>
          <min>0.3</min>
          <max>12</max>
        </range>
      </ray>
      <plugin filename="libgazebo_ros_ray_sensor.so" name="laser_controller">
        <ros>
          <argument>~/out:=scan</argument>
        </ros>
        <output_type>sensor_msgs/LaserScan</output_type>
        <frame_name>laser_frame</frame_name>
      </plugin>
    </sensor>
  </gazebo>
  <!-- Predefine some colors, can be later used to color code robot-->
  <material name="white">
    <color rgba="1 1 1 1"/>
  </material>
  <material name="orange">
    <color rgba="1 0.3 0.1 1"/>
  </material>
  <material name="blue">
    <color rgba="0.2 0.2 1 1"/>
  </material>
  <!-- This first link called "world" is empty -->
  <link name="world"/>
  <!-- A simple fixed joint from our empty world link, to our base. -->
  <!-- The base origin is offset from the world origin. -->
  <joint name="base_joint" type="fixed">
    <origin rpy="0 0 0" xyz="0 0 0"/>
    <parent link="world"/>
    <child link="base_link"/>
  </joint>
  <!--Hollow Steel Base Frame-->
  <link name="base_link">
    <visual>
      <origin rpy="0 0 0" xyz="0 0 0"/>
      <geometry>
        <box size="0.61 0.61 0.02"/>
      </geometry>
      <material name="orange"/>
    </visual>
    <collision>
      <origin rpy="0 0 0" xyz="0 0 0"/>
      <geometry>
        <box size="0.61 0.61 0.02"/>
      </geometry>
    </collision>
    <inertial>
      <mass value="1"/>
      <inertia ixx="1" ixy="1" ixz="1" iyy="1" iyz="1" izz="1"/>
    </inertial>
  </link>
  <!--Electrical Box-->
  <link name="elecBox">
    <visual>
      <origin rpy="0 0 0" xyz="0 -0.15 0.09"/>
      <geometry>
        <box size="0.61 0.25 0.15"/>
      </geometry>
      <material name="orange"/>
    </visual>
    <collision>
      <origin rpy="0 0 0" xyz="0 -0.15 0.09"/>
      <geometry>
        <box size="0.61 0.25 0.15"/>
      </geometry>
    </collision>
    <inertial>
      <mass value="1"/>
      <inertia ixx="1" ixy="1" ixz="1" iyy="1" iyz="1" izz="1"/>
    </inertial>
  </link>
  <joint name="elect_to_base_link" type="fixed">
    <parent link="base_link"/>
    <child link="elecBox"/>
  </joint>
  <!--Camera Pole-->
  <link name="camPole">
    <visual>
      <origin rpy="0 0 0" xyz="0 0 0.3"/>
      <geometry>
        <cylinder length="0.56" radius="0.01"/>
      </geometry>
      <material name="orange"/>
    </visual>
    <collision>
      <origin rpy="0 0 0" xyz="0 0 0.3"/>
      <geometry>
        <cylinder length="0.56" radius="0.01"/>
      </geometry>
    </collision>
    <inertial>
      <mass value="1"/>
      <inertia ixx="1" ixy="1" ixz="1" iyy="1" iyz="1" izz="1"/>
    </inertial>
  </link>
  <joint name="pole_to_base_link" type="fixed">
    <parent link="base_link"/>
    <child link="camPole"/>
  </joint>
  <!--Camera On Pole Mount-->
  <link name="topCameraMount">
    <visual>
      <origin rpy="0 0 0" xyz="0 0 0.03"/>
      <geometry>
        <box size="0.01 0.01 0.01"/>
      </geometry>
      <material name="orange"/>
    </visual>
    <collision>
      <origin rpy="0 0 0" xyz="0 0 0.05"/>
      <geometry>
        <box size="0.01 0.01 0.01"/>
      </geometry>
    </collision>
    <inertial>
      <mass value="1"/>
      <inertia ixx="1" ixy="1" ixz="1" iyy="1" iyz="1" izz="1"/>
    </inertial>
  </link>
  <joint name="camera_vertical_link" type="revolute">
    <parent link="camPole"/>
    <child link="topCameraMount"/>
    <limit effort="10" lower="-0.6" upper="0.6" velocity="1.0"/>
    <origin rpy="0 0 0" xyz="0 0 0.58"/>
  </joint>
  <!--Camera On Pole-->
  <link name="topCamera">
    <visual>
      <origin rpy="0 0 0" xyz="0 0 0"/>
      <geometry>
        <box size="0.05 0.05 0.05"/>
      </geometry>
      <material name="orange"/>
    </visual>
    <collision>
      <origin rpy="0 0 0" xyz="0 0 0"/>
      <geometry>
        <box size="0.05 0.05 0.05"/>
      </geometry>
    </collision>
    <inertial>
      <mass value="1"/>
      <inertia ixx="1" ixy="1" ixz="1" iyy="1" iyz="1" izz="1"/>
    </inertial>
  </link>
  <joint name="cam_horizontal_link" type="revolute">
    <parent link="topCameraMount"/>
    <child link="topCamera"/>
    <limit effort="10" lower="-1.57" upper="1.57" velocity="1.0"/>
    <origin rpy="0 1.57 0" xyz="0 0 0"/>
  </joint>
  <!--lidar-->
  <link name="laser_frame">
    <visual>
      <origin rpy="0 0 0" xyz="0 0 0"/>
      <geometry>
        <cylinder length="0.04" radius="0.05"/>
      </geometry>
      <material name="orange"/>
    </visual>
    <collision>
      <origin rpy="0 0 0" xyz="0 0 0"/>
      <geometry>
        <cylinder length="0.04" radius="0.05"/>
      </geometry>
    </collision>
    <inertial>
      <mass value="1"/>
      <inertia ixx="1" ixy="1" ixz="1" iyy="1" iyz="1" izz="1"/>
    </inertial>
  </link>
  <joint name="lidar_base_link" type="fixed">
    <parent link="base_link"/>
    <child link="laser_frame"/>
    <origin rpy="0 0 0" xyz="0 0.25 0.02"/>
  </joint>
  <!--Left Rocker Bogiee-->
  <link name="lb">
    <visual>
      <origin rpy="-0.9 0 0" xyz="0.31 -0.13 -0.08"/>
      <geometry>
        <cylinder length="0.3" radius="0.015"/>
      </geometry>
      <material name="orange"/>
    </visual>
    <collision>
      <origin rpy="-0.9 0 0" xyz="0.31 -0.13 -0.08"/>
      <geometry>
        <cylinder length="0.3" radius="0.015"/>
      </geometry>
    </collision>
    <inertial>
      <mass value="1"/>
      <inertia ixx="1" ixy="1" ixz="1" iyy="1" iyz="1" izz="1"/>
    </inertial>
  </link>
  <link name="lr">
    <visual>
      <origin rpy="0.8 0 0" xyz="0.31 0.235 -0.18"/>
      <geometry>
        <cylinder length="0.52" radius="0.015"/>
      </geometry>
      <material name="orange"/>
    </visual>
    <collision>
      <origin rpy="0.8 0 0" xyz="0.31 0.235 -0.18"/>
      <geometry>
        <cylinder length="0.52" radius="0.015"/>
      </geometry>
    </collision>
    <inertial>
      <mass value="1"/>
      <inertia ixx="1" ixy="1" ixz="1" iyy="1" iyz="1" izz="1"/>
    </inertial>
  </link>
  <joint name="lr_to_lb" type="fixed">
    <parent link="lr"/>
    <child link="lb"/>
  </joint>
  <joint name="lr_to_base_link" type="revolute">
    <parent link="base_link"/>
    <child link="lr"/>
    <limit effort="10" lower="-0.6" upper="0.6" velocity="1.0"/>
  </joint>
  <!--Left Bogiee-->
  <link name="lbb">
    <visual>
      <origin rpy="-1 0 0" xyz="0 -0.13 -0.1"/>
      <geometry>
        <cylinder length="0.27" radius="0.015"/>
      </geometry>
      <material name="orange"/>
    </visual>
    <collision>
      <origin rpy="-1 0 0" xyz="0 -0.13 -0.1"/>
      <geometry>
        <cylinder length="0.27" radius="0.015"/>
      </geometry>
    </collision>
    <inertial>
      <mass value="1"/>
      <inertia ixx="1" ixy="1" ixz="1" iyy="1" iyz="1" izz="1"/>
    </inertial>
  </link>
  <link name="lbf">
    <visual>
      <origin rpy="1 0 0" xyz="0 0.12 -0.1"/>
      <geometry>
        <cylinder length="0.27" radius="0.015"/>
      </geometry>
      <material name="orange"/>
    </visual>
    <collision>
      <origin rpy="1 0 0" xyz="0 0.12 -0.1"/>
      <geometry>
        <cylinder length="0.27" radius="0.015"/>
      </geometry>
    </collision>
    <inertial>
      <mass value="1"/>
      <inertia ixx="1" ixy="1" ixz="1" iyy="1" iyz="1" izz="1"/>
    </inertial>
  </link>
  <joint name="lbb_to_lbf" type="fixed">
    <parent link="lbb"/>
    <child link="lbf"/>
  </joint>
  <joint name="lbb_to_lb" type="revolute">
    <parent link="lb"/>
    <child link="lbb"/>
    <limit effort="10" lower="-0.4" upper="0.4" velocity="1.0"/>
    <origin rpy="0 0 0" xyz="0.31 -0.25 -0.18"/>
  </joint>
  <!--Left Rocker Bogiee Wheels-->
  <link name="lw1">
    <visual>
      <origin rpy="0 1.57 0" xyz="0 0 0"/>
      <geometry>
        <cylinder length="0.14" radius="0.115"/>
      </geometry>
      <material name="orange"/>
    </visual>
    <collision>
      <origin rpy="0 1.57 0" xyz="0 0 0"/>
      <geometry>
        <cylinder length="0.14" radius="0.115"/>
      </geometry>
    </collision>
    <inertial>
      <mass value="1"/>
      <inertia ixx="1" ixy="1" ixz="1" iyy="1" iyz="1" izz="1"/>
    </inertial>
  </link>
  <link name="lw2">
    <visual>
      <origin rpy="0 1.57 0" xyz="0 0 0"/>
      <geometry>
        <cylinder length="0.14" radius="0.115"/>
      </geometry>
      <material name="orange"/>
    </visual>
    <collision>
      <origin rpy="0 1.57 0" xyz="0 0 0"/>
      <geometry>
        <cylinder length="0.14" radius="0.115"/>
      </geometry>
    </collision>
    <inertial>
      <mass value="1"/>
      <inertia ixx="1" ixy="1" ixz="1" iyy="1" iyz="1" izz="1"/>
    </inertial>
  </link>
  <link name="lw3">
    <visual>
      <origin rpy="0 1.57 0" xyz="0 0 0"/>
      <geometry>
        <cylinder length="0.14" radius="0.115"/>
      </geometry>
      <material name="orange"/>
    </visual>
    <collision>
      <origin rpy="0 1.57 0" xyz="0 0 0"/>
      <geometry>
        <cylinder length="0.14" radius="0.115"/>
      </geometry>
    </collision>
    <inertial>
      <mass value="1"/>
      <inertia ixx="1" ixy="1" ixz="1" iyy="1" iyz="1" izz="1"/>
    </inertial>
  </link>
  <joint name="lw1_to_lrb" type="continuous">
    <parent link="lr"/>
    <child link="lw1"/>
    <axiz rpy="0 0 0" xyz="0 0 0"/>
    <origin rpy="0 0 0" xyz="0.4 0.43 -0.36"/>
  </joint>
  <joint name="lw2_to_lrb" type="continuous">
    <parent link="lbf"/>
    <child link="lw2"/>
    <axiz rpy="0 0 0" xyz="0 0 0"/>
    <origin rpy="0 0 0" xyz="0.09 0.25 -0.16"/>
  </joint>
  <joint name="lw3_to_lrb" type="continuous">
    <parent link="lbb"/>
    <child link="lw3"/>
    <axiz rpy="0 0 0" xyz="0 0 0"/>
    <origin rpy="0 0 0" xyz="0.09 -0.25 -0.16"/>
  </joint>
  <!--Right Rocker Bogiee-->
  <link name="rb">
    <visual>
      <origin rpy="-0.9 0 0" xyz="-0.31 -0.13 -0.08"/>
      <geometry>
        <cylinder length="0.3" radius="0.015"/>
      </geometry>
      <material name="orange"/>
    </visual>
    <collision>
      <origin rpy="-0.9 0 0" xyz="-0.31 -0.13 -0.08"/>
      <geometry>
        <cylinder length="0.3" radius="0.015"/>
      </geometry>
    </collision>
    <inertial>
      <mass value="1"/>
      <inertia ixx="1" ixy="1" ixz="1" iyy="1" iyz="1" izz="1"/>
    </inertial>
  </link>
  <link name="rr">
    <visual>
      <origin rpy="0.8 0 0" xyz="-0.31 0.235 -0.18"/>
      <geometry>
        <cylinder length="0.52" radius="0.015"/>
      </geometry>
      <material name="orange"/>
    </visual>
    <collision>
      <origin rpy="0.8 0 0" xyz="-0.31 0.235 -0.18"/>
      <geometry>
        <cylinder length="0.52" radius="0.015"/>
      </geometry>
    </collision>
    <inertial>
      <mass value="1"/>
      <inertia ixx="1" ixy="1" ixz="1" iyy="1" iyz="1" izz="1"/>
    </inertial>
  </link>
  <joint name="rr_to_rb" type="fixed">
    <parent link="rr"/>
    <child link="rb"/>
  </joint>
  <joint name="rrb_to_base_link" type="revolute">
    <parent link="base_link"/>
    <child link="rr"/>
    <limit effort="10" lower="-0.8" upper="0.8" velocity="1.0"/>
  </joint>
  <!--Right Bogiee-->
  <link name="rbb">
    <visual>
      <origin rpy="-1 0 0" xyz="0 -0.13 -0.1"/>
      <geometry>
        <cylinder length="0.27" radius="0.015"/>
      </geometry>
      <material name="orange"/>
    </visual>
    <collision>
      <origin rpy="-1 0 0" xyz="0 -0.13 -0.1"/>
      <geometry>
        <cylinder length="0.27" radius="0.015"/>
      </geometry>
    </collision>
    <inertial>
      <mass value="1"/>
      <inertia ixx="1" ixy="1" ixz="1" iyy="1" iyz="1" izz="1"/>
    </inertial>
  </link>
  <link name="rbf">
    <visual>
      <origin rpy="1 0 0" xyz="0 0.12 -0.1"/>
      <geometry>
        <cylinder length="0.27" radius="0.015"/>
      </geometry>
      <material name="orange"/>
    </visual>
    <collision>
      <origin rpy="1 0 0" xyz="0 0.12 -0.1"/>
      <geometry>
        <cylinder length="0.27" radius="0.015"/>
      </geometry>
    </collision>
    <inertial>
      <mass value="1"/>
      <inertia ixx="1" ixy="1" ixz="1" iyy="1" iyz="1" izz="1"/>
    </inertial>
  </link>
  <joint name="rbb_to_rbf" type="fixed">
    <parent link="rbb"/>
    <child link="rbf"/>
  </joint>
  <joint name="rbb_to_rb" type="revolute">
    <parent link="rb"/>
    <child link="rbb"/>
    <limit effort="10" lower="-0.4" upper="0.4" velocity="1.0"/>
    <origin rpy="0 0 0" xyz="-0.31 -0.25 -0.18"/>
  </joint>
  <!--Right Rocker Bogiee Wheels-->
  <link name="rw1">
    <visual>
      <origin rpy="0 1.57 0" xyz="0 0 0"/>
      <geometry>
        <cylinder length="0.14" radius="0.115"/>
      </geometry>
      <material name="orange"/>
    </visual>
    <collision>
      <origin rpy="0 1.57 0" xyz="0 0 0"/>
      <geometry>
        <cylinder length="0.14" radius="0.115"/>
      </geometry>
    </collision>
    <inertial>
      <mass value="1"/>
      <inertia ixx="1" ixy="1" ixz="1" iyy="1" iyz="1" izz="1"/>
    </inertial>
  </link>
  <link name="rw2">
    <visual>
      <origin rpy="0 1.57 0" xyz="0 0 0"/>
      <geometry>
        <cylinder length="0.14" radius="0.115"/>
      </geometry>
      <material name="orange"/>
    </visual>
    <collision>
      <origin rpy="0 1.57 0" xyz="0 0 0"/>
      <geometry>
        <cylinder length="0.14" radius="0.115"/>
      </geometry>
    </collision>
    <inertial>
      <mass value="1"/>
      <inertia ixx="1" ixy="1" ixz="1" iyy="1" iyz="1" izz="1"/>
    </inertial>
  </link>
  <link name="rw3">
    <visual>
      <origin rpy="0 1.57 0" xyz="0 0 0"/>
      <geometry>
        <cylinder length="0.14" radius="0.115"/>
      </geometry>
      <material name="orange"/>
    </visual>
    <collision>
      <origin rpy="0 1.57 0" xyz="0 0 0"/>
      <geometry>
        <cylinder length="0.14" radius="0.115"/>
      </geometry>
    </collision>
    <inertial>
      <mass value="1"/>
      <inertia ixx="1" ixy="1" ixz="1" iyy="1" iyz="1" izz="1"/>
    </inertial>
  </link>
  <joint name="rw1_to_rrb" type="continuous">
    <parent link="rr"/>
    <child link="rw1"/>
    <axiz rpy="0 0 0" xyz="0 0 0"/>
    <origin rpy="0 0 0" xyz="-0.4 0.43 -0.36"/>
  </joint>
  <joint name="rw2_to_rrb" type="continuous">
    <parent link="rbf"/>
    <child link="rw2"/>
    <axiz rpy="0 0 0" xyz="0 0 0"/>
    <origin rpy="0 0 0" xyz="-0.09 0.25 -0.16"/>
  </joint>
  <joint name="rw3_to_rrb" type="continuous">
    <parent link="rbb"/>
    <child link="rw3"/>
    <axiz rpy="0 0 0" xyz="0 0 0"/>
    <origin rpy="0 0 0" xyz="-0.09 -0.25 -0.16"/>
  </joint>
  <gazebo>
    <plugin filename="libgazebo_ros_control.so" name="gazebo_ros_control">
      <robotNamespace>/robot</robotNamespace>
    </plugin>
  </gazebo>
</robot>

