<?xml version="1.0" encoding="utf-8" ?>
<!-- This URDF was automatically created by SolidWorks to URDF Exporter! Originally created by Stephen Brawner (brawner@gmail.com)
     Commit Version: 1.6.0-1-g15f4949  Build Version: 1.6.7594.29634
     For more information, please see http://wiki.ros.org/sw_urdf_exporter -->
<robot name="wroboarm_21">
    <link name="turntable">

        <inertial>
            <origin xyz="-2.82541936962439E-17 6.93889390390723E-18 -4.24870678161208E-34" rpy="0 0 0" />
            <mass value="0.396806230030924" />
            <inertia ixx="0.000571454150237484" ixy="-2.23834839552239E-21" ixz="1.37054783361242E-37" iyy="0.000571454150237484" iyz="3.23777898172651E-20" izz="0.00110024104924718" />
        </inertial>

        <visual>
            <origin xyz="0 0 0" rpy="0 0 0" />
            <geometry>
                <mesh filename="package://wroboarm_21/meshes/turntable.STL" />
            </geometry>
            <material name="">
                <color rgba="0.792156862745098 0.819607843137255 0.933333333333333 1" />
            </material>
        </visual>
        <collision>
            <origin xyz="0 0 0" rpy="0 0 0" />
            <geometry>
                <mesh filename="package://wroboarm_21/meshes/turntable.STL" />
            </geometry>
        </collision>
    </link>
    <link name="gearbox">

        <inertial>
            <origin xyz="-5.70181409604587E-18 0.0380153243966357 -0.00138922050969218" rpy="0 0 0" />
            <mass value="0.341209853046385" />
            <inertia ixx="0.000637264883384741" ixy="6.24923664103596E-20" ixz="-2.71681384497167E-19" iyy="0.000834504397618049" iyz="1.62941368108056E-05" izz="0.000889318878925749" />
        </inertial>

        <visual>
            <origin xyz="0 0 0" rpy="0 0 0" />
            <geometry>
                <mesh filename="package://wroboarm_21/meshes/gearbox.STL" />
            </geometry>
            <material name="">
                <color rgba="0.792156862745098 0.819607843137255 0.933333333333333 1" />
            </material>
        </visual>
        <collision>
            <origin xyz="0 0 0" rpy="0 0 0" />
            <geometry>
                <mesh filename="package://wroboarm_21/meshes/gearbox.STL" />
            </geometry>
        </collision>
    </link>
    <joint name="link1_joint" type="revolute">
        <origin xyz="0 0 0.0127" rpy="1.5708 0 0" />
        <parent link="turntable" />
        <child link="gearbox" />
        <axis xyz="0 1 0" />
        <limit effort="50" velocity="1.5" lower="-3.1" upper="3.1"/>
    </joint>
    <link name="upperarm">

        <inertial>
            <origin xyz="1.49614561175028E-17 0.157206632847804 2.77555756156289E-17" rpy="0 0 0" />
            <mass value="1.26412421587631" />
            <inertia ixx="0.0136779903910557" ixy="3.22448390771324E-19" ixz="3.96119838307109E-20" iyy="0.000964387075304149" iyz="-2.67429553724681E-18" izz="0.0140917496737089" />
        </inertial>

        <visual>
            <origin xyz="0 0 0" rpy="0 0 0" />
            <geometry>
                <mesh filename="package://wroboarm_21/meshes/upperarm.STL" />
            </geometry>
            <material name="">
                <color rgba="0.792156862745098 0.819607843137255 0.933333333333333 1" />
            </material>
        </visual>
        <collision>
            <origin xyz="0 0 0" rpy="0 0 0" />
            <geometry>
                <mesh filename="package://wroboarm_21/meshes/upperarm.STL" />
            </geometry>
        </collision>
    </link>
    <joint name="link2_joint" type="revolute">
        <origin xyz="0 0.07239 0.03683" rpy="0 0 0" />
        <parent link="gearbox" />
        <child link="upperarm" />
        <axis xyz="1 0 0" />
        <limit effort="50" velocity="1.5" lower="-0.349" upper="0.78539"/>
    </joint>
    <link name="elbow">

        <inertial>
            <origin xyz="7.33210423758527E-18 0.0462797200039115 -0.00991708285798099" rpy="0 0 0" />
            <mass value="0.625328404239412" />
            <inertia ixx="0.00150936287881219" ixy="7.22519589370286E-20" ixz="2.65311197270661E-20" iyy="0.000771504125821615" iyz="-1.13468871077225E-05" izz="0.00102329905512323" />
        </inertial>

        <visual>
            <origin xyz="0 0 0" rpy="0 0 0" />
            <geometry>
                <mesh filename="package://wroboarm_21/meshes/elbow.STL" />
            </geometry>
            <material name="">
                <color rgba="0.792156862745098 0.819607843137255 0.933333333333333 1" />
            </material>
        </visual>
        <collision>
            <origin xyz="0 0 0" rpy="0 0 0" />
            <geometry>
                <mesh filename="package://wroboarm_21/meshes/elbow.STL" />
            </geometry>
        </collision>
    </link>
    <joint name="link3_joint" type="revolute">
        <origin xyz="0 0.381 0" rpy="-1.5708 0 0" />
        <parent link="upperarm" />
        <child link="elbow" />
        <axis xyz="1 0 0" />
        <limit effort="50" velocity="1.5" lower="0" upper="3.1"/>
    </joint>
    <link name="forearm">

        <inertial>
            <origin xyz="-1.32860243738577E-17 -1.90819582357449E-17 -0.113066392198771" rpy="0 0 0" />
            <mass value="0.460632401231927" />
            <inertia ixx="0.00223620566444836" ixy="2.86239968572403E-21" ixz="-5.06454254732662E-20" iyy="0.00224684031586386" iyz="-3.05817065058502E-19" izz="0.000245602268076572" />
        </inertial>

        <visual>
            <origin xyz="0 0 0" rpy="0 0 0" />
            <geometry>
                <mesh filename="package://wroboarm_21/meshes/forearm.STL" />
            </geometry>
            <material name="">
                <color rgba="0.792156862745098 0.819607843137255 0.933333333333333 1" />
            </material>
        </visual>
        <collision>
            <origin xyz="0 0 0" rpy="0 0 0" />
            <geometry>
                <mesh filename="package://wroboarm_21/meshes/forearm.STL" />
            </geometry>
        </collision>
    </link>
    <joint name="link4_joint" type="revolute">
        <origin xyz="0 0.04445 0.04445" rpy="3.1416 0 0" />
        <parent link="elbow" />
        <child link="forearm" />
        <axis xyz="0 0 1" />
        <limit effort="50" velocity="1.5" lower="-3.1" upper="3.1"/>
    </joint>
    <link name="wrist">

        <inertial>
            <origin xyz="-7.1276563552947E-09 7.80625564189563E-18 -3.41498918032812E-09" rpy="0 0 0" />
            <mass value="0.0642008901362293" />
            <inertia ixx="3.49809093099438E-05" ixy="5.28878027298075E-11" ixz="1.56594471999825E-18" iyy="2.42909279281571E-05" iyz="-4.37083043679572E-11" izz="2.86709715099874E-05" />
        </inertial>

        <visual>
            <origin xyz="0 0 0" rpy="0 0 0" />
            <geometry>
                <mesh filename="package://wroboarm_21/meshes/wrist.STL" />
            </geometry>
            <material name="">
                <color rgba="0.792156862745098 0.819607843137255 0.933333333333333 1" />
            </material>
        </visual>
        <collision>
            <origin xyz="0 0 0" rpy="0 0 0" />
            <geometry>
                <mesh filename="package://wroboarm_21/meshes/wrist.STL" />
            </geometry>
        </collision>
    </link>
    <joint name="link5_joint" type="revolute">
        <origin xyz="0 0 -0.254" rpy="3.1416 0 0" />
        <parent link="forearm" />
        <child link="wrist" />
        <axis xyz="1 0 0" />
        <limit effort="50" velocity="1.5" lower="-3.1" upper="3.1"/>
    </joint>

    <link name="dummy">
    </link>

    <joint name="link6_joint" type="revolute">

        <origin xyz="0 0 0" rpy="0 0 0" />
        <parent link="wrist" />
        <child link="dummy" />
        <axis xyz="1 0 0" />
        <limit effort="50" velocity="1.5" lower="-1.5707963267948966" upper="1.5707963267948966"/>

    </joint>

    <link name="manipulator">

        <inertial>
            <origin xyz="5.8113236445223E-17 1.74020910368395E-17 -0.05715" rpy="0 0 0" />
            <mass value="0.237050487139156" />
            <inertia ixx="0.000319176967769642" ixy="-3.08271195529153E-21" ixz="3.16873566981017E-20" iyy="0.000319176967769642" iyz="7.05373762522642E-20" izz="0.000122196649085178" />
        </inertial>

        <visual>
            <origin xyz="0 0 0" rpy="0 0 0" />
            <geometry>
                <mesh filename="package://wroboarm_21/meshes/manipulator.STL" />
            </geometry>
            <material name="">
                <color rgba="0.792156862745098 0.819607843137255 0.933333333333333 1" />
            </material>
        </visual>
        <collision>
            <origin xyz="0 0 0" rpy="0 0 0" />
            <geometry>
                <mesh filename="package://wroboarm_21/meshes/manipulator.STL" />
            </geometry>
        </collision>
    </link>
    <joint name="link7_joint" type="revolute">
        <origin xyz="0 0 0.0254" rpy="3.1416 0 0" />
        <parent link="dummy" />
        <child link="manipulator" />
        <axis xyz="0 0 1" />
        <limit effort="50" velocity="1.5" lower="-3.15" upper="3.15"/>
    </joint>

    <transmission name="trans_link1_joint">
        <type>transmission_interface/SimpleTransmission</type>
        <joint name="link1_joint">
            <hardwareInterface>hardware_interface/EffortJointInterface</hardwareInterface>
        </joint>
        <actuator name="link1_joint_motor">
            <hardwareInterface>hardware_interface/EffortJointInterface</hardwareInterface>
            <mechanicalReduction>1</mechanicalReduction>
        </actuator>
    </transmission>
    <transmission name="trans_link2_joint">
        <type>transmission_interface/SimpleTransmission</type>
        <joint name="link2_joint">
            <hardwareInterface>hardware_interface/EffortJointInterface</hardwareInterface>
        </joint>
        <actuator name="link2_joint_motor">
            <hardwareInterface>hardware_interface/EffortJointInterface</hardwareInterface>
            <mechanicalReduction>1</mechanicalReduction>
        </actuator>
    </transmission>
    <transmission name="trans_link3_joint">
        <type>transmission_interface/SimpleTransmission</type>
        <joint name="link3_joint">
            <hardwareInterface>hardware_interface/EffortJointInterface</hardwareInterface>
        </joint>
        <actuator name="link3_joint_motor">
            <hardwareInterface>hardware_interface/EffortJointInterface</hardwareInterface>
            <mechanicalReduction>1</mechanicalReduction>
        </actuator>
    </transmission>
    <transmission name="trans_link4_joint">
        <type>transmission_interface/SimpleTransmission</type>
        <joint name="link4_joint">
            <hardwareInterface>hardware_interface/EffortJointInterface</hardwareInterface>
        </joint>
        <actuator name="link4_joint_motor">
            <hardwareInterface>hardware_interface/EffortJointInterface</hardwareInterface>
            <mechanicalReduction>1</mechanicalReduction>
        </actuator>
    </transmission>
    <transmission name="trans_link5_joint">
        <type>transmission_interface/SimpleTransmission</type>
        <joint name="link5_joint">
            <hardwareInterface>hardware_interface/EffortJointInterface</hardwareInterface>
        </joint>
        <actuator name="link5_joint_motor">
            <hardwareInterface>hardware_interface/EffortJointInterface</hardwareInterface>
            <mechanicalReduction>1</mechanicalReduction>
        </actuator>
    </transmission>
    <transmission name="trans_link6_joint">
        <type>transmission_interface/SimpleTransmission</type>
        <joint name="link6_joint">
            <hardwareInterface>hardware_interface/EffortJointInterface</hardwareInterface>
        </joint>
        <actuator name="link6_joint_motor">
            <hardwareInterface>hardware_interface/EffortJointInterface</hardwareInterface>
            <mechanicalReduction>1</mechanicalReduction>
        </actuator>
    </transmission>
    <transmission name="trans_link7_joint">
        <type>transmission_interface/SimpleTransmission</type>
        <joint name="link6_joint">
            <hardwareInterface>hardware_interface/EffortJointInterface</hardwareInterface>
        </joint>
        <actuator name="link6_joint_motor">
            <hardwareInterface>hardware_interface/EffortJointInterface</hardwareInterface>
            <mechanicalReduction>1</mechanicalReduction>
        </actuator>
    </transmission>
    <gazebo>
        <plugin name="gazebo_ros_control" filename="libgazebo_ros_control.so">
            <robotNamespace>/</robotNamespace>
        </plugin>
    </gazebo>
</robot>
